<mujoco model="SpiRob">
  <compiler angle="radian" inertiafromgeom="true" autolimits="true"/>
  <option timestep="0.002" gravity="0.0 0.0 -9.81" integrator="implicit"/>
  <visual>
    <quality shadowsize="4096"/>
    <map znear="0.01" zfar="20"/>
    <scale connect="0"/>
  </visual>

  <!-- ===== DEFAULTS: edit these to tune global behavior ===== -->
  <default>
    <geom density="1200.0" margin="0.001"
          rgba="0.2 0.35 0.65 1.0"
          friction="0.6 0.01 0.001"/>
    <site size="0.001"/>
    <joint damping="0.01" stiffness="0.05" limited="false"/>
    <motor ctrllimited="true" ctrlrange="-5.0 0.0" gear="1.0"/>
  </default>

  <asset>
    <mesh name="link_001" file="meshes\link_001.stl"/>
    <mesh name="link_002" file="meshes\link_002.stl"/>
    <mesh name="link_003" file="meshes\link_003.stl"/>
    <mesh name="link_004" file="meshes\link_004.stl"/>
    <mesh name="link_005" file="meshes\link_005.stl"/>
    <mesh name="link_006" file="meshes\link_006.stl"/>
    <mesh name="link_007" file="meshes\link_007.stl"/>
    <mesh name="link_008" file="meshes\link_008.stl"/>
    <mesh name="link_009" file="meshes\link_009.stl"/>
    <mesh name="link_010" file="meshes\link_010.stl"/>
    <mesh name="link_011" file="meshes\link_011.stl"/>
    <mesh name="link_012" file="meshes\link_012.stl"/>
    <mesh name="link_013" file="meshes\link_013.stl"/>
    <mesh name="link_014" file="meshes\link_014.stl"/>
    <mesh name="link_015" file="meshes\link_015.stl"/>
    <mesh name="link_016" file="meshes\link_016.stl"/>
    <mesh name="link_017" file="meshes\link_017.stl"/>
    <mesh name="link_018" file="meshes\link_018.stl"/>
    <mesh name="link_019" file="meshes\link_019.stl"/>
    <mesh name="link_020" file="meshes\link_020.stl"/>
    <mesh name="link_021" file="meshes\link_021.stl"/>
  </asset>

  <worldbody>
    <light name="light1" diffuse="1 1 1" active="true" pos="0 -0.5 0.01" dir="0 1 0"/>
    <light name="light2" diffuse="1 1 1" active="true" pos="-0.01 -0.5 0.5" dir="0 0 -1"/>
    <light name="light3" diffuse="1 1 1" active="true" pos="0 -0.1 1.5" dir="0 0 -1"/>
    <geom type="plane" size="2 2 0.05" rgba="0.9 0.9 0.9 1"/>
    <body name="link_001" pos="9.201534098006623e-17 0.0 0.003204676108156501" quat="0.9999999999999989 0.0 -2.0265051502934331e-16 -0.0">
      <joint name="j_001" type="ball"/>
      <geom name="gmesh_001" type="mesh" mesh="link_001" group="1"/>
      <site name="c0_001_s1" pos="-0.017466993738933023 0.0 0.0064417392977900514"/> <site name="c0_001_s2" pos="-0.01746699373893302 0.0 0.012934492045517589"/> <site name="c1_001_s1" pos="0.008733496869466374 -0.015126860305659656 0.006441739297790041"/> <site name="c1_001_s2" pos="0.008733496869466376 -0.015126860305659656 0.012934492045517578"/> <site name="c2_001_s1" pos="0.008733496869466385 0.015126860305659651 0.006441739297790041"/> <site name="c2_001_s2" pos="0.008733496869466386 0.015126860305659651 0.012934492045517578"/>

    <body name="link_002" pos="0.0 0.0 0.014679218087922385" quat="0.9999999999999989 0.0 2.267115779592851e-16 0.0">
      <joint name="j_002" type="ball"/>
      <geom name="gmesh_002" type="mesh" mesh="link_002" group="1"/>
      <site name="c0_002_s1" pos="-0.015931188921888266 0.0 0.007371374279879938"/> <site name="c0_002_s2" pos="-0.01593118892188827 0.0 0.015561736087811445"/> <site name="c1_002_s1" pos="0.007965594460944 -0.013796814318844388 0.007371374279879939"/> <site name="c1_002_s2" pos="0.007965594460944001 -0.01379681431884439 0.015561736087811445"/> <site name="c2_002_s1" pos="0.00796559446094401 0.013796814318844384 0.007371374279879939"/> <site name="c2_002_s2" pos="0.007965594460944012 0.013796814318844386 0.015561736087811445"/>

    <body name="link_003" pos="0.0 0.0 0.018517277935725662" quat="0.9999999999999989 0.0 2.4888340552575934e-17 0.0">
      <joint name="j_003" type="ball"/>
      <geom name="gmesh_003" type="mesh" mesh="link_003" group="1"/>
      <site name="c0_003_s1" pos="-0.0147051779522689 0.0 0.006804097991047168"/> <site name="c0_003_s2" pos="-0.014705177952268904 0.0 0.01436415697155574"/> <site name="c1_003_s1" pos="0.007352588976134316 -0.012735057673835625 0.006804097991047171"/> <site name="c1_003_s2" pos="0.007352588976134316 -0.012735057673835627 0.014364156971555742"/> <site name="c2_003_s1" pos="0.007352588976134326 0.012735057673835622 0.006804097991047171"/> <site name="c2_003_s2" pos="0.007352588976134326 0.012735057673835624 0.014364156971555742"/>

    <body name="link_004" pos="0.0 0.0 0.017092250212559446" quat="0.9999999999999989 0.0 3.0213085282659427e-17 0.0">
      <joint name="j_004" type="ball"/>
      <geom name="gmesh_004" type="mesh" mesh="link_004" group="1"/>
      <site name="c0_004_s1" pos="-0.013573516682787863 0.0 0.006280477386440079"/> <site name="c0_004_s2" pos="-0.013573516682787858 0.0 0.013258739535179307"/> <site name="c1_004_s1" pos="0.006786758341393795 -0.011755010265986096 0.006280477386440082"/> <site name="c1_004_s2" pos="0.006786758341393791 -0.011755010265986092 0.013258739535179311"/> <site name="c2_004_s1" pos="0.006786758341393803 0.011755010265986094 0.006280477386440082"/> <site name="c2_004_s2" pos="0.0067867583413938 0.011755010265986089 0.013258739535179311"/>

    <body name="link_005" pos="0.0 0.0 0.015776887852673893" quat="0.9999999999999989 0.0 -1.5314412010148087e-16 0.0">
      <joint name="j_005" type="ball"/>
      <geom name="gmesh_005" type="mesh" mesh="link_005" group="1"/>
      <site name="c0_005_s1" pos="-0.012528944276359023 0.0 0.005797152870738483"/> <site name="c0_005_s2" pos="-0.012528944276359026 0.0 0.0122383913243109"/> <site name="c1_005_s1" pos="0.0062644721381793726 -0.010850384025926476 0.00579715287073848"/> <site name="c1_005_s2" pos="0.006264472138179376 -0.010850384025926479 0.012238391324310897"/> <site name="c2_005_s1" pos="0.00626447213817938 0.010850384025926472 0.00579715287073848"/> <site name="c2_005_s2" pos="0.006264472138179384 0.010850384025926477 0.012238391324310897"/>

    <body name="link_006" pos="0.0 0.0 0.01456275137681698" quat="0.9999999999999989 0.0 -2.9948116073343956e-15 0.0">
      <joint name="j_006" type="ball"/>
      <geom name="gmesh_006" type="mesh" mesh="link_006" group="1"/>
      <site name="c0_006_s1" pos="-0.011564758665612702 0.0 0.005351023391831857"/> <site name="c0_006_s2" pos="-0.0115647586656127 0.0 0.011296565696125404"/> <site name="c1_006_s1" pos="0.005782379332806264 -0.010015374793056779 0.00535102339183175"/> <site name="c1_006_s2" pos="0.005782379332806318 -0.010015374793056808 0.011296565696125298"/> <site name="c2_006_s1" pos="0.005782379332806272 0.010015374793056775 0.00535102339183175"/> <site name="c2_006_s2" pos="0.005782379332806326 0.010015374793056806 0.011296565696125298"/>

    <body name="link_007" pos="0.0 0.0 0.013442050779808395" quat="0.9999999999999989 0.0 2.9773580553475247e-15 0.0">
      <joint name="j_007" type="ball"/>
      <geom name="gmesh_007" type="mesh" mesh="link_007" group="1"/>
      <site name="c0_007_s1" pos="-0.010674773551848754 0.0 0.0049392265441990674"/> <site name="c0_007_s2" pos="-0.010674773551848756 0.0 0.01042721981551459"/> <site name="c1_007_s1" pos="0.005337386775924367 -0.00924462507554726 0.004939226544199065"/> <site name="c1_007_s2" pos="0.0053373867759243685 -0.009244625075547262 0.010427219815514586"/> <site name="c2_007_s1" pos="0.005337386775924374 0.009244625075547257 0.004939226544199065"/> <site name="c2_007_s2" pos="0.0053373867759243755 0.009244625075547259 0.010427219815514586"/>

    <body name="link_008" pos="0.0 0.0 0.012407595549189424" quat="0.9999999999999989 0.0 7.651755397152339e-17 0.0">
      <joint name="j_008" type="ball"/>
      <geom name="gmesh_008" type="mesh" mesh="link_008" group="1"/>
      <site name="c0_008_s1" pos="-0.00985327871320629 0.0 0.004559120203466202"/> <site name="c0_008_s2" pos="-0.009853278713206287 0.0 0.00962477588373191"/> <site name="c1_008_s1" pos="0.004926639356603136 -0.008533189676205089 0.004559120203466202"/> <site name="c1_008_s2" pos="0.004926639356603135 -0.008533189676205087 0.00962477588373191"/> <site name="c2_008_s1" pos="0.004926639356603143 0.008533189676205087 0.004559120203466202"/> <site name="c2_008_s2" pos="0.004926639356603142 0.008533189676205085 0.00962477588373191"/>

    <body name="link_009" pos="0.0 0.0 0.011452748530270077" quat="0.9999999999999989 0.0 4.804851811769712e-17 0.0">
      <joint name="j_009" type="ball"/>
      <geom name="gmesh_009" type="mesh" mesh="link_009" group="1"/>
      <site name="c0_009_s1" pos="-0.009095003367383822 0.0 0.0042082655743064514"/> <site name="c0_009_s2" pos="-0.00909500336738382 0.0 0.008884085350750331"/> <site name="c1_009_s1" pos="0.004547501683691904 -0.0078765039636594 0.004208265574306452"/> <site name="c1_009_s2" pos="0.004547501683691902 -0.0078765039636594 0.008884085350750331"/> <site name="c2_009_s1" pos="0.00454750168369191 0.007876503963659399 0.004208265574306452"/> <site name="c2_009_s2" pos="0.0045475016836919084 0.007876503963659397 0.008884085350750331"/>

    <body name="link_010" pos="0.0 0.0 0.01057138334156707" quat="0.9999999999999989 0.0 -7.302398845032509e-17 0.0">
      <joint name="j_010" type="ball"/>
      <geom name="gmesh_010" type="mesh" mesh="link_010" group="1"/>
      <site name="c0_010_s1" pos="-0.008395082353841798 0.0 0.003884411542917577"/> <site name="c0_010_s2" pos="-0.0083950823538418 0.0 0.008200395881718309"/> <site name="c1_010_s1" pos="0.00419754117692089 -0.007270354585289455 0.003884411542917576"/> <site name="c1_010_s2" pos="0.004197541176920892 -0.007270354585289456 0.008200395881718309"/> <site name="c2_010_s1" pos="0.004197541176920895 0.007270354585289453 0.003884411542917576"/> <site name="c2_010_s2" pos="0.004197541176920897 0.007270354585289454 0.008200395881718309"/>

    <body name="link_011" pos="0.0 0.0 0.009757845067408122" quat="0.9999999999999989 0.0 -8.819192595672664e-17 0.0">
      <joint name="j_011" type="ball"/>
      <geom name="gmesh_011" type="mesh" mesh="link_011" group="1"/>
      <site name="c0_011_s1" pos="-0.007749024918509591 0.0 0.003585480233679913"/> <site name="c0_011_s2" pos="-0.007749024918509589 0.0 0.007569320865565917"/> <site name="c1_011_s1" pos="0.0038745124592547892 -0.0067108524339879435 0.00358548023367991"/> <site name="c1_011_s2" pos="0.0038745124592547897 -0.006710852433987943 0.007569320865565914"/> <site name="c2_011_s1" pos="0.0038745124592547944 0.006710852433987942 0.00358548023367991"/> <site name="c2_011_s2" pos="0.003874512459254795 0.006710852433987941 0.007569320865565914"/>

    <body name="link_012" pos="0.0 0.0 0.009006913975501296" quat="0.9999999999999989 0.0 1.2967630674290876e-16 0.0">
      <joint name="j_012" type="ball"/>
      <geom name="gmesh_012" type="mesh" mesh="link_012" group="1"/>
      <site name="c0_012_s1" pos="-0.007152685900717032 0.0 0.0033095536773256606"/> <site name="c0_012_s2" pos="-0.007152685900717034 0.0 0.0069868112701267915"/> <site name="c1_012_s1" pos="0.003576342950358512 -0.006194407695311728 0.0033095536773256606"/> <site name="c1_012_s2" pos="0.003576342950358513 -0.006194407695311729 0.0069868112701267915"/> <site name="c2_012_s1" pos="0.003576342950358517 0.0061944076953117265 0.0033095536773256606"/> <site name="c2_012_s2" pos="0.0035763429503585177 0.006194407695311727 0.0069868112701267915"/>

    <body name="link_013" pos="0.0 0.0 0.008313772026678407" quat="0.9999999999999989 0.0 1.3954097849488682e-17 0.0">
      <joint name="j_013" type="ball"/>
      <geom name="gmesh_013" type="mesh" mesh="link_013" group="1"/>
      <site name="c0_013_s1" pos="-0.006602239137483155 0.0 0.003054861505081663"/> <site name="c0_013_s2" pos="-0.006602239137483156 0.0 0.006449129663196246"/> <site name="c1_013_s1" pos="0.003301119568741574 -0.005717706814920272 0.003054861505081663"/> <site name="c1_013_s2" pos="0.0033011195687415746 -0.005717706814920273 0.006449129663196246"/> <site name="c2_013_s1" pos="0.0033011195687415785 0.0057177068149202705 0.003054861505081663"/> <site name="c2_013_s2" pos="0.003301119568741579 0.005717706814920271 0.006449129663196246"/>

    <body name="link_014" pos="0.0 0.0 0.007673971961937587" quat="0.9999999999999989 0.0 1.7667064599478886e-17 0.0">
      <joint name="j_014" type="ball"/>
      <geom name="gmesh_014" type="mesh" mesh="link_014" group="1"/>
      <site name="c0_014_s1" pos="-0.006094152914521888 0.0 0.002819769589829074"/> <site name="c0_014_s2" pos="-0.006094152914521888 0.0 0.005952826232840658"/> <site name="c1_014_s1" pos="0.00304707645726094 -0.005277691238522931 0.0028197695898290742"/> <site name="c1_014_s2" pos="0.0030470764572609397 -0.005277691238522931 0.005952826232840658"/> <site name="c2_014_s1" pos="0.003047076457260944 0.005277691238522929 0.0028197695898290742"/> <site name="c2_014_s2" pos="0.0030470764572609436 0.005277691238522929 0.005952826232840658"/>

    <body name="link_015" pos="0.0 0.0 0.007083408768442323" quat="0.9999999999999989 0.0 -7.038556109038006e-19 0.0">
      <joint name="j_015" type="ball"/>
      <geom name="gmesh_015" type="mesh" mesh="link_015" group="1"/>
      <site name="c0_015_s1" pos="-0.005625167306456169 0.0 0.0026027695614018183"/> <site name="c0_015_s2" pos="-0.005625167306456168 0.0 0.005494716653104692"/> <site name="c1_015_s1" pos="0.0028125836532280797 -0.004871537787928725 0.0026027695614018187"/> <site name="c1_015_s2" pos="0.002812583653228079 -0.0048715377879287244 0.005494716653104692"/> <site name="c2_015_s1" pos="0.0028125836532280836 0.004871537787928724 0.0026027695614018187"/> <site name="c2_015_s2" pos="0.0028125836532280827 0.004871537787928723 0.005494716653104692"/>

    <body name="link_016" pos="0.0 0.0 0.006538293341402462" quat="0.9999999999999989 0.0 -3.040727752437489e-16 0.0">
      <joint name="j_016" type="ball"/>
      <geom name="gmesh_016" type="mesh" mesh="link_016" group="1"/>
      <site name="c0_016_s1" pos="-0.005192273260853322 0.0 0.002402469128752613"/> <site name="c0_016_s2" pos="-0.005192273260853323 0.0 0.005071861653098922"/> <site name="c1_016_s1" pos="0.002596136630426658 -0.004496640547289642 0.002402469128752609"/> <site name="c1_016_s2" pos="0.0025961366304266603 -0.004496640547289644 0.005071861653098917"/> <site name="c2_016_s1" pos="0.0025961366304266616 0.004496640547289641 0.002402469128752609"/> <site name="c2_016_s2" pos="0.0025961366304266638 0.004496640547289642 0.005071861653098917"/>

    <body name="link_017" pos="0.0 0.0 0.0060351281728483475" quat="0.9999999999999989 0.0 1.4294430778093038e-16 0.0">
      <joint name="j_017" type="ball"/>
      <geom name="gmesh_017" type="mesh" mesh="link_017" group="1"/>
      <site name="c0_017_s1" pos="-0.004792693291883063 0.0 0.0022175831468925224"/> <site name="c0_017_s2" pos="-0.0047926932918830635 0.0 0.0046815481583824545"/> <site name="c1_017_s1" pos="0.002396346645941532 -0.004150594143318001 0.0022175831468925207"/> <site name="c1_017_s2" pos="0.0023963466459415335 -0.004150594143318002 0.004681548158382453"/> <site name="c2_017_s1" pos="0.0023963466459415352 0.004150594143318 0.0022175831468925207"/> <site name="c2_017_s2" pos="0.0023963466459415365 0.004150594143318001 0.004681548158382453"/>

    <body name="link_018" pos="-1.925929944387236e-34 0.0 0.0055706849113159596" quat="0.9999999999999989 0.0 4.111740376231239e-17 0.0">
      <joint name="j_018" type="ball"/>
      <geom name="gmesh_018" type="mesh" mesh="link_018" group="1"/>
      <site name="c0_018_s1" pos="-0.00442386365972694 0.0 0.0020469253712887"/> <site name="c0_018_s2" pos="-0.004423863659726939 0.0 0.004321271883641121"/> <site name="c1_018_s1" pos="0.0022119318298634725 -0.0038311783122023293 0.002046925371288699"/> <site name="c1_018_s2" pos="0.002211931829863473 -0.0038311783122023293 0.00432127188364112"/> <site name="c2_018_s1" pos="0.0022119318298634756 0.0038311783122023284 0.002046925371288699"/> <site name="c2_018_s2" pos="0.002211931829863476 0.0038311783122023284 0.00432127188364112"/>

    <body name="link_019" pos="0.0 0.0 0.005141983648462745" quat="0.9999999999999989 0.0 1.157111553399235e-16 0.0">
      <joint name="j_019" type="ball"/>
      <geom name="gmesh_019" type="mesh" mesh="link_019" group="1"/>
      <site name="c0_019_s1" pos="-0.004083417921400788 0.0 0.0018894008468168242"/> <site name="c0_019_s2" pos="-0.004083417921400789 0.0 0.00398872126497557"/> <site name="c1_019_s1" pos="0.0020417089607003974 -0.003536343654201733 0.0018894008468168246"/> <site name="c1_019_s2" pos="0.0020417089607003974 -0.003536343654201734 0.00398872126497557"/> <site name="c2_019_s1" pos="0.0020417089607004 0.0035363436542017322 0.0018894008468168246"/> <site name="c2_019_s2" pos="0.0020417089607004 0.0035363436542017327 0.00398872126497557"/>

    <body name="link_020" pos="0.0 0.0 0.004746273799717121" quat="0.9999999999999989 0.0 -5.293319430239881e-17 0.0">
      <joint name="j_020" type="ball"/>
      <geom name="gmesh_020" type="mesh" mesh="link_020" group="1"/>
      <site name="c0_020_s1" pos="-0.0037691717474508113 0.0 0.0017439988824334287"/> <site name="c0_020_s2" pos="-0.003769171747450811 0.0 0.0036817626287060923"/> <site name="c1_020_s1" pos="0.0018845858737254087 -0.0032641984845189894 0.0017439988824334285"/> <site name="c1_020_s2" pos="0.0018845858737254087 -0.003264198484518989 0.0036817626287060923"/> <site name="c2_020_s1" pos="0.0018845858737254113 0.0032641984845189886 0.0017439988824334285"/> <site name="c2_020_s2" pos="0.0018845858737254113 0.003264198484518988 0.0036817626287060923"/>

    <body name="link_021" pos="0.0 0.0 0.004381016456288356" quat="0.9999999999999989 0.0 3.8617927082517215e-16 0.0">
      <joint name="j_021" type="ball"/>
      <geom name="gmesh_021" type="mesh" mesh="link_021" group="1"/>
      <site name="c0_021_s1" pos="-0.0034791089071059137 0.0 0.0016097865664945173"/> <site name="c0_021_s2" pos="-0.0034791089071059137 0.0 0.0033984265015369304"/> <site name="c1_021_s1" pos="0.0017395544535529586 -0.0030129966960864376 0.0016097865664945212"/> <site name="c1_021_s2" pos="0.0017395544535529566 -0.0030129966960864363 0.0033984265015369343"/> <site name="c2_021_s1" pos="0.001739554453552961 0.0030129966960864367 0.0016097865664945212"/> <site name="c2_021_s2" pos="0.001739554453552959 0.003012996696086436 0.0033984265015369343"/>
    </body>
    </body>
    </body>
    </body>
    </body>
    </body>
    </body>
    </body>
    </body>
    </body>
    </body>
    </body>
    </body>
    </body>
    </body>
    </body>
    </body>
    </body>
    </body>
    </body>
    </body>
  </worldbody>
  <tendon>
    <spatial name="cable_0" width="0.0006">
      <site site="c0_021_s2"/>
      <site site="c0_021_s1"/>
      <site site="c0_020_s1"/>
      <site site="c0_019_s1"/>
      <site site="c0_018_s1"/>
      <site site="c0_017_s1"/>
      <site site="c0_016_s1"/>
      <site site="c0_015_s1"/>
      <site site="c0_014_s1"/>
      <site site="c0_013_s1"/>
      <site site="c0_012_s1"/>
      <site site="c0_011_s1"/>
      <site site="c0_010_s1"/>
      <site site="c0_009_s1"/>
      <site site="c0_008_s1"/>
      <site site="c0_007_s1"/>
      <site site="c0_006_s1"/>
      <site site="c0_005_s1"/>
      <site site="c0_004_s1"/>
      <site site="c0_003_s1"/>
      <site site="c0_002_s1"/>
      <site site="c0_001_s1"/>
    </spatial>
    <spatial name="cable_1" width="0.0006">
      <site site="c1_021_s2"/>
      <site site="c1_021_s1"/>
      <site site="c1_020_s1"/>
      <site site="c1_019_s1"/>
      <site site="c1_018_s1"/>
      <site site="c1_017_s1"/>
      <site site="c1_016_s1"/>
      <site site="c1_015_s1"/>
      <site site="c1_014_s1"/>
      <site site="c1_013_s1"/>
      <site site="c1_012_s1"/>
      <site site="c1_011_s1"/>
      <site site="c1_010_s1"/>
      <site site="c1_009_s1"/>
      <site site="c1_008_s1"/>
      <site site="c1_007_s1"/>
      <site site="c1_006_s1"/>
      <site site="c1_005_s1"/>
      <site site="c1_004_s1"/>
      <site site="c1_003_s1"/>
      <site site="c1_002_s1"/>
      <site site="c1_001_s1"/>
    </spatial>
    <spatial name="cable_2" width="0.0006">
      <site site="c2_021_s2"/>
      <site site="c2_021_s1"/>
      <site site="c2_020_s1"/>
      <site site="c2_019_s1"/>
      <site site="c2_018_s1"/>
      <site site="c2_017_s1"/>
      <site site="c2_016_s1"/>
      <site site="c2_015_s1"/>
      <site site="c2_014_s1"/>
      <site site="c2_013_s1"/>
      <site site="c2_012_s1"/>
      <site site="c2_011_s1"/>
      <site site="c2_010_s1"/>
      <site site="c2_009_s1"/>
      <site site="c2_008_s1"/>
      <site site="c2_007_s1"/>
      <site site="c2_006_s1"/>
      <site site="c2_005_s1"/>
      <site site="c2_004_s1"/>
      <site site="c2_003_s1"/>
      <site site="c2_002_s1"/>
      <site site="c2_001_s1"/>
    </spatial>
  </tendon>
  <actuator>
    <motor name="motor_c0" tendon="cable_0"/>
    <motor name="motor_c1" tendon="cable_1"/>
    <motor name="motor_c2" tendon="cable_2"/>
  </actuator>
</mujoco>
